<?xml version="1.0"?>
<robot name="basic_robot">
  <!-- Basic differential drive robot for testing -->
  <link name="base_link">
    <visual>
      <geometry>
        <box size="0.5 0.4 0.2"/>
      </geometry>
      <material name="white">
        <color rgba="1 1 1 1"/>
      </material>
    </visual>
    <collision>
      <geometry>
        <box size="0.5 0.4 0.2"/>
      </geometry>
    </collision>
    <inertial>
      <mass value="10.0"/>
      <inertia ixx="0.416" ixy="0.0" ixz="0.0" iyy="0.541" iyz="0.0" izz="0.241"/>
    </inertial>
  </link>

  <link name="left_wheel">
    <visual>
      <geometry>
        <cylinder radius="0.1" length="0.05"/>
      </geometry>
      <origin rpy="1.5708 0 0"/>
      <material name="black">
        <color rgba="0 0 0 1"/>
      </material>
    </visual>
    <collision>
      <geometry>
        <cylinder radius="0.1" length="0.05"/>
      </geometry>
      <origin rpy="1.5708 0 0"/>
    </collision>
    <inertial>
      <mass value="1.0"/>
      <inertia ixx="0.005" ixy="0.0" ixz="0.0" iyy="0.005" iyz="0.0" izz="0.01"/>
    </inertial>
  </link>

  <link name="right_wheel">
    <visual>
      <geometry>
        <cylinder radius="0.1" length="0.05"/>
      </geometry>
      <origin rpy="1.5708 0 0"/>
      <material name="black">
        <color rgba="0 0 0 1"/>
      </material>
    </visual>
    <collision>
      <geometry>
        <cylinder radius="0.1" length="0.05"/>
      </geometry>
      <origin rpy="1.5708 0 0"/>
    </collision>
    <inertial>
      <mass value="1.0"/>
      <inertia ixx="0.005" ixy="0.0" ixz="0.0" iyy="0.005" iyz="0.0" izz="0.01"/>
    </inertial>
  </link>

  <joint name="left_wheel_joint" type="continuous">
    <parent link="base_link"/>
    <child link="left_wheel"/>
    <origin xyz="0 0.2 -0.1" rpy="0 0 0"/>
    <axis xyz="0 0 1"/>
  </joint>

  <joint name="right_wheel_joint" type="continuous">
    <parent link="base_link"/>
    <child link="right_wheel"/>
    <origin xyz="0 -0.2 -0.1" rpy="0 0 0"/>
    <axis xyz="0 0 1"/>
  </joint>
</robot>