<?xml version="1.0" ?>
<sdf version="1.10">
  <model name="basic_robot">
    <link name="base_link">
      <pose>0 0 0.1 0 0 0</pose>
      <inertial>
        <mass>10.0</mass>
        <inertia>
          <ixx>0.416</ixx>
          <ixy>0</ixy>
          <ixz>0</ixz>
          <iyy>0.541</iyy>
          <iyz>0</iyz>
          <izz>0.241</izz>
        </inertia>
      </inertial>
      <visual name="visual">
        <geometry>
          <box>
            <size>0.5 0.4 0.2</size>
          </box>
        </geometry>
        <material>
          <ambient>1 1 1 1</ambient>
          <diffuse>1 1 1 1</diffuse>
        </material>
      </visual>
      <collision name="collision">
        <geometry>
          <box>
            <size>0.5 0.4 0.2</size>
          </box>
        </geometry>
      </collision>
    </link>

    <link name="left_wheel">
      <pose>0 0.2 -0.1 0 0 0</pose>
      <inertial>
        <mass>1.0</mass>
        <inertia>
          <ixx>0.005</ixx>
          <ixy>0</ixy>
          <ixz>0</ixz>
          <iyy>0.005</iyy>
          <iyz>0</iyz>
          <izz>0.01</izz>
        </inertia>
      </inertial>
      <visual name="visual">
        <geometry>
          <cylinder>
            <radius>0.1</radius>
            <length>0.05</length>
          </cylinder>
        </geometry>
        <pose>0 0 0 1.5708 0 0</pose>
        <material>
          <ambient>0 0 0 1</ambient>
          <diffuse>0 0 0 1</diffuse>
        </material>
      </visual>
      <collision name="collision">
        <geometry>
          <cylinder>
            <radius>0.1</radius>
            <length>0.05</length>
          </cylinder>
        </geometry>
        <pose>0 0 0 1.5708 0 0</pose>
      </collision>
    </link>

    <link name="right_wheel">
      <pose>0 -0.2 -0.1 0 0 0</pose>
      <inertial>
        <mass>1.0</mass>
        <inertia>
          <ixx>0.005</ixx>
          <ixy>0</ixy>
          <ixz>0</ixz>
          <iyy>0.005</iyy>
          <iyz>0</iyz>
          <izz>0.01</izz>
        </inertia>
      </inertial>
      <visual name="visual">
        <geometry>
          <cylinder>
            <radius>0.1</radius>
            <length>0.05</length>
          </cylinder>
        </geometry>
        <pose>0 0 0 1.5708 0 0</pose>
        <material>
          <ambient>0 0 0 1</ambient>
          <diffuse>0 0 0 1</diffuse>
        </material>
      </visual>
      <collision name="collision">
        <geometry>
          <cylinder>
            <radius>0.1</radius>
            <length>0.05</length>
          </cylinder>
        </geometry>
        <pose>0 0 0 1.5708 0 0</pose>
      </collision>
    </link>

    <joint name="left_wheel_joint" type="revolute">
      <parent>base_link</parent>
      <child>left_wheel</child>
      <axis>
        <xyz>0 0 1</xyz>
      </axis>
    </joint>

    <joint name="right_wheel_joint" type="revolute">
      <parent>base_link</parent>
      <child>right_wheel</child>
      <axis>
        <xyz>0 0 1</xyz>
      </axis>
    </joint>
  </model>
</sdf>