<?xml version="1.0" ?>
<sdf version="1.10">
  <model name="humanoid_robot">
    <!-- Torso -->
    <link name="torso">
      <pose>0 0 0.5 0 0 0</pose>
      <inertial>
        <mass>5.0</mass>
        <inertia>
          <ixx>0.2</ixx>
          <ixy>0</ixy>
          <ixz>0</ixz>
          <iyy>0.2</iyy>
          <iyz>0</iyz>
          <izz>0.2</izz>
        </inertia>
      </inertial>

      <visual name="torso_visual">
        <geometry>
          <box>
            <size>0.3 0.2 0.5</size>
          </box>
        </geometry>
        <material>
          <ambient>1.0 0.0 0.0 1.0</ambient>
          <diffuse>1.0 0.0 0.0 1.0</diffuse>
          <specular>1.0 0.0 0.0 1.0</specular>
        </material>
      </visual>

      <collision name="torso_collision">
        <geometry>
          <box>
            <size>0.3 0.2 0.5</size>
          </box>
        </geometry>
      </collision>
    </link>

    <!-- Head -->
    <link name="head">
      <pose>0 0 1.0 0 0 0</pose>
      <inertial>
        <mass>1.0</mass>
        <inertia>
          <ixx>0.01</ixx>
          <ixy>0</ixy>
          <ixz>0</ixz>
          <iyy>0.01</iyy>
          <iyz>0</iyz>
          <izz>0.01</izz>
        </inertia>
      </inertial>

      <visual name="head_visual">
        <geometry>
          <sphere>
            <radius>0.1</radius>
          </sphere>
        </geometry>
        <material>
          <ambient>1.0 1.0 1.0 1.0</ambient>
          <diffuse>1.0 1.0 1.0 1.0</diffuse>
          <specular>1.0 1.0 1.0 1.0</specular>
        </material>
      </visual>

      <collision name="head_collision">
        <geometry>
          <sphere>
            <radius>0.1</radius>
          </sphere>
        </geometry>
      </collision>
    </link>

    <!-- Right arm -->
    <link name="right_upper_arm">
      <pose>0.1 0.1 0.6 0 0 0</pose>
      <inertial>
        <mass>0.5</mass>
        <inertia>
          <ixx>0.01</ixx>
          <ixy>0</ixy>
          <ixz>0</ixz>
          <iyy>0.01</iyy>
          <iyz>0</iyz>
          <izz>0.01</izz>
        </inertia>
      </inertial>

      <visual name="right_upper_arm_visual">
        <geometry>
          <cylinder>
            <radius>0.05</radius>
            <length>0.3</length>
          </cylinder>
        </geometry>
        <material>
          <ambient>0.0 0.0 1.0 1.0</ambient>
          <diffuse>0.0 0.0 1.0 1.0</diffuse>
          <specular>0.0 0.0 1.0 1.0</specular>
        </material>
      </visual>

      <collision name="right_upper_arm_collision">
        <geometry>
          <cylinder>
            <radius>0.05</radius>
            <length>0.3</length>
          </cylinder>
        </geometry>
      </collision>
    </link>

    <link name="right_lower_arm">
      <pose>0.1 0.4 0.6 0 0 0</pose>
      <inertial>
        <mass>0.3</mass>
        <inertia>
          <ixx>0.005</ixx>
          <ixy>0</ixy>
          <ixz>0</ixz>
          <iyy>0.005</iyy>
          <iyz>0</iyz>
          <izz>0.005</izz>
        </inertia>
      </inertial>

      <visual name="right_lower_arm_visual">
        <geometry>
          <cylinder>
            <radius>0.04</radius>
            <length>0.25</length>
          </cylinder>
        </geometry>
        <material>
          <ambient>0.0 0.0 1.0 1.0</ambient>
          <diffuse>0.0 0.0 1.0 1.0</diffuse>
          <specular>0.0 0.0 1.0 1.0</specular>
        </material>
      </visual>

      <collision name="right_lower_arm_collision">
        <geometry>
          <cylinder>
            <radius>0.04</radius>
            <length>0.25</length>
          </cylinder>
        </geometry>
      </collision>
    </link>

    <!-- Left arm -->
    <link name="left_upper_arm">
      <pose>0.1 -0.1 0.6 0 0 0</pose>
      <inertial>
        <mass>0.5</mass>
        <inertia>
          <ixx>0.01</ixx>
          <ixy>0</ixy>
          <ixz>0</ixz>
          <iyy>0.01</iyy>
          <iyz>0</iyz>
          <izz>0.01</izz>
        </inertia>
      </inertial>

      <visual name="left_upper_arm_visual">
        <geometry>
          <cylinder>
            <radius>0.05</radius>
            <length>0.3</length>
          </cylinder>
        </geometry>
        <material>
          <ambient>0.0 0.0 1.0 1.0</ambient>
          <diffuse>0.0 0.0 1.0 1.0</diffuse>
          <specular>0.0 0.0 1.0 1.0</specular>
        </material>
      </visual>

      <collision name="left_upper_arm_collision">
        <geometry>
          <cylinder>
            <radius>0.05</radius>
            <length>0.3</length>
          </cylinder>
        </geometry>
      </collision>
    </link>

    <link name="left_lower_arm">
      <pose>0.1 -0.4 0.6 0 0 0</pose>
      <inertial>
        <mass>0.3</mass>
        <inertia>
          <ixx>0.005</ixx>
          <ixy>0</ixy>
          <ixz>0</ixz>
          <iyy>0.005</iyy>
          <iyz>0</iyz>
          <izz>0.005</izz>
        </inertia>
      </inertial>

      <visual name="left_lower_arm_visual">
        <geometry>
          <cylinder>
            <radius>0.04</radius>
            <length>0.25</length>
          </cylinder>
        </geometry>
        <material>
          <ambient>0.0 0.0 1.0 1.0</ambient>
          <diffuse>0.0 0.0 1.0 1.0</diffuse>
          <specular>0.0 0.0 1.0 1.0</specular>
        </material>
      </visual>

      <collision name="left_lower_arm_collision">
        <geometry>
          <cylinder>
            <radius>0.04</radius>
            <length>0.25</length>
          </cylinder>
        </geometry>
      </collision>
    </link>

    <!-- Right leg -->
    <link name="right_upper_leg">
      <pose>-0.15 0 0.1 0 0 0</pose>
      <inertial>
        <mass>1.0</mass>
        <inertia>
          <ixx>0.02</ixx>
          <ixy>0</ixy>
          <ixz>0</ixz>
          <iyy>0.02</iyy>
          <iyz>0</iyz>
          <izz>0.02</izz>
        </inertia>
      </inertial>

      <visual name="right_upper_leg_visual">
        <geometry>
          <cylinder>
            <radius>0.06</radius>
            <length>0.4</length>
          </cylinder>
        </geometry>
        <material>
          <ambient>0.0 1.0 0.0 1.0</ambient>
          <diffuse>0.0 1.0 0.0 1.0</diffuse>
          <specular>0.0 1.0 0.0 1.0</specular>
        </material>
      </visual>

      <collision name="right_upper_leg_collision">
        <geometry>
          <cylinder>
            <radius>0.06</radius>
            <length>0.4</length>
          </cylinder>
        </geometry>
      </collision>
    </link>

    <link name="right_lower_leg">
      <pose>-0.15 0 -0.3 0 0 0</pose>
      <inertial>
        <mass>0.8</mass>
        <inertia>
          <ixx>0.01</ixx>
          <ixy>0</ixy>
          <ixz>0</ixz>
          <iyy>0.01</iyy>
          <iyz>0</iyz>
          <izz>0.01</izz>
        </inertia>
      </inertial>

      <visual name="right_lower_leg_visual">
        <geometry>
          <cylinder>
            <radius>0.05</radius>
            <length>0.35</length>
          </cylinder>
        </geometry>
        <material>
          <ambient>0.0 1.0 0.0 1.0</ambient>
          <diffuse>0.0 1.0 0.0 1.0</diffuse>
          <specular>0.0 1.0 0.0 1.0</specular>
        </material>
      </visual>

      <collision name="right_lower_leg_collision">
        <geometry>
          <cylinder>
            <radius>0.05</radius>
            <length>0.35</length>
          </cylinder>
        </geometry>
      </collision>
    </link>

    <link name="right_foot">
      <pose>-0.15 0 -0.65 0 0 0</pose>
      <inertial>
        <mass>0.5</mass>
        <inertia>
          <ixx>0.001</ixx>
          <ixy>0</ixy>
          <ixz>0</ixz>
          <iyy>0.001</iyy>
          <iyz>0</iyz>
          <izz>0.001</izz>
        </inertia>
      </inertial>

      <visual name="right_foot_visual">
        <geometry>
          <box>
            <size>0.2 0.1 0.05</size>
          </box>
        </geometry>
        <material>
          <ambient>0.0 0.0 0.0 1.0</ambient>
          <diffuse>0.0 0.0 0.0 1.0</diffuse>
          <specular>0.0 0.0 0.0 1.0</specular>
        </material>
      </visual>

      <collision name="right_foot_collision">
        <geometry>
          <box>
            <size>0.2 0.1 0.05</size>
          </box>
        </geometry>
      </collision>
    </link>

    <!-- Left leg -->
    <link name="left_upper_leg">
      <pose>-0.15 0 0.1 0 0 0</pose>
      <inertial>
        <mass>1.0</mass>
        <inertia>
          <ixx>0.02</ixx>
          <ixy>0</ixy>
          <ixz>0</ixz>
          <iyy>0.02</iyy>
          <iyz>0</iyz>
          <izz>0.02</izz>
        </inertia>
      </inertial>

      <visual name="left_upper_leg_visual">
        <geometry>
          <cylinder>
            <radius>0.06</radius>
            <length>0.4</length>
          </cylinder>
        </geometry>
        <material>
          <ambient>0.0 1.0 0.0 1.0</ambient>
          <diffuse>0.0 1.0 0.0 1.0</diffuse>
          <specular>0.0 1.0 0.0 1.0</specular>
        </material>
      </visual>

      <collision name="left_upper_leg_collision">
        <geometry>
          <cylinder>
            <radius>0.06</radius>
            <length>0.4</length>
          </cylinder>
        </geometry>
      </collision>
    </link>

    <link name="left_lower_leg">
      <pose>-0.15 0 -0.3 0 0 0</pose>
      <inertial>
        <mass>0.8</mass>
        <inertia>
          <ixx>0.01</ixx>
          <ixy>0</ixy>
          <ixz>0</ixz>
          <iyy>0.01</iyy>
          <iyz>0</iyz>
          <izz>0.01</izz>
        </inertia>
      </inertial>

      <visual name="left_lower_leg_visual">
        <geometry>
          <cylinder>
            <radius>0.05</radius>
            <length>0.35</length>
          </cylinder>
        </geometry>
        <material>
          <ambient>0.0 1.0 0.0 1.0</ambient>
          <diffuse>0.0 1.0 0.0 1.0</diffuse>
          <specular>0.0 1.0 0.0 1.0</specular>
        </material>
      </visual>

      <collision name="left_lower_leg_collision">
        <geometry>
          <cylinder>
            <radius>0.05</radius>
            <length>0.35</length>
          </cylinder>
        </geometry>
      </collision>
    </link>

    <link name="left_foot">
      <pose>-0.15 0 -0.65 0 0 0</pose>
      <inertial>
        <mass>0.5</mass>
        <inertia>
          <ixx>0.001</ixx>
          <ixy>0</ixy>
          <ixz>0</ixz>
          <iyy>0.001</iyy>
          <iyz>0</iyz>
          <izz>0.001</izz>
        </inertia>
      </inertial>

      <visual name="left_foot_visual">
        <geometry>
          <box>
            <size>0.2 0.1 0.05</size>
          </box>
        </geometry>
        <material>
          <ambient>0.0 0.0 0.0 1.0</ambient>
          <diffuse>0.0 0.0 0.0 1.0</diffuse>
          <specular>0.0 0.0 0.0 1.0</specular>
        </material>
      </visual>

      <collision name="left_foot_collision">
        <geometry>
          <box>
            <size>0.2 0.1 0.05</size>
          </box>
        </geometry>
      </collision>
    </link>

    <!-- Joints -->
    <joint name="torso_head_joint" type="revolute">
      <parent>torso</parent>
      <child>head</child>
      <axis>
        <xyz>0 1 0</xyz>
        <limit>
          <lower>-0.5</lower>
          <upper>0.5</upper>
        </limit>
      </axis>
    </joint>

    <joint name="right_shoulder_joint" type="revolute">
      <parent>torso</parent>
      <child>right_upper_arm</child>
      <axis>
        <xyz>0 0 1</xyz>
        <limit>
          <lower>-1.57</lower>
          <upper>1.57</upper>
        </limit>
      </axis>
    </joint>

    <joint name="right_elbow_joint" type="revolute">
      <parent>right_upper_arm</parent>
      <child>right_lower_arm</child>
      <axis>
        <xyz>0 1 0</xyz>
        <limit>
          <lower>0</lower>
          <upper>2.35</upper>
        </limit>
      </axis>
    </joint>

    <joint name="left_shoulder_joint" type="revolute">
      <parent>torso</parent>
      <child>left_upper_arm</child>
      <axis>
        <xyz>0 0 1</xyz>
        <limit>
          <lower>-1.57</lower>
          <upper>1.57</upper>
        </limit>
      </axis>
    </joint>

    <joint name="left_elbow_joint" type="revolute">
      <parent>left_upper_arm</parent>
      <child>left_lower_arm</child>
      <axis>
        <xyz>0 1 0</xyz>
        <limit>
          <lower>0</lower>
          <upper>2.35</upper>
        </limit>
      </axis>
    </joint>

    <joint name="right_hip_joint" type="revolute">
      <parent>torso</parent>
      <child>right_upper_leg</child>
      <axis>
        <xyz>0 1 0</xyz>
        <limit>
          <lower>-1.57</lower>
          <upper>0.78</upper>
        </limit>
      </axis>
    </joint>

    <joint name="right_knee_joint" type="revolute">
      <parent>right_upper_leg</parent>
      <child>right_lower_leg</child>
      <axis>
        <xyz>0 1 0</xyz>
        <limit>
          <lower>0</lower>
          <upper>2.35</upper>
        </limit>
      </axis>
    </joint>

    <joint name="right_ankle_joint" type="revolute">
      <parent>right_lower_leg</parent>
      <child>right_foot</child>
      <axis>
        <xyz>0 0 1</xyz>
        <limit>
          <lower>-0.78</lower>
          <upper>0.78</upper>
        </limit>
      </axis>
    </joint>

    <joint name="left_hip_joint" type="revolute">
      <parent>torso</parent>
      <child>left_upper_leg</child>
      <axis>
        <xyz>0 1 0</xyz>
        <limit>
          <lower>-1.57</lower>
          <upper>0.78</upper>
        </limit>
      </axis>
    </joint>

    <joint name="left_knee_joint" type="revolute">
      <parent>left_upper_leg</parent>
      <child>left_lower_leg</child>
      <axis>
        <xyz>0 1 0</xyz>
        <limit>
          <lower>0</lower>
          <upper>2.35</upper>
        </limit>
      </axis>
    </joint>

    <joint name="left_ankle_joint" type="revolute">
      <parent>left_lower_leg</parent>
      <child>left_foot</child>
      <axis>
        <xyz>0 0 1</xyz>
        <limit>
          <lower>-0.78</lower>
          <upper>0.78</upper>
        </limit>
      </axis>
    </joint>
  </model>
</sdf>